[2023-05-30 14:01:35,216] {taskinstance.py:903} INFO - Dependencies all met for <TaskInstance: agile_data_science_batch_prediction_model_training.pyspark_train_classifier_model 2023-05-30T11:56:10.604104+00:00 [queued]>
[2023-05-30 14:01:35,229] {taskinstance.py:903} INFO - Dependencies all met for <TaskInstance: agile_data_science_batch_prediction_model_training.pyspark_train_classifier_model 2023-05-30T11:56:10.604104+00:00 [queued]>
[2023-05-30 14:01:35,229] {taskinstance.py:1095} INFO - 
--------------------------------------------------------------------------------
[2023-05-30 14:01:35,229] {taskinstance.py:1096} INFO - Starting attempt 1 of 4
[2023-05-30 14:01:35,230] {taskinstance.py:1097} INFO - 
--------------------------------------------------------------------------------
[2023-05-30 14:01:35,267] {taskinstance.py:1115} INFO - Executing <Task(BashOperator): pyspark_train_classifier_model> on 2023-05-30T11:56:10.604104+00:00
[2023-05-30 14:01:35,274] {standard_task_runner.py:52} INFO - Started process 135272 to run task
[2023-05-30 14:01:35,284] {standard_task_runner.py:76} INFO - Running: ['airflow', 'tasks', 'run', 'agile_data_science_batch_prediction_model_training', 'pyspark_train_classifier_model', '2023-05-30T11:56:10.604104+00:00', '--job-id', '3', '--pool', 'default_pool', '--raw', '--subdir', '/home/lucia/practica_creativa/resources/airflow/dags/setup.py', '--cfg-path', '/tmp/tmp1qa_ev84', '--error-file', '/tmp/tmp64_jsmmb']
[2023-05-30 14:01:35,285] {standard_task_runner.py:77} INFO - Job 3: Subtask pyspark_train_classifier_model
[2023-05-30 14:01:35,493] {logging_mixin.py:109} INFO - Running <TaskInstance: agile_data_science_batch_prediction_model_training.pyspark_train_classifier_model 2023-05-30T11:56:10.604104+00:00 [running]> on host lucia-Virtual-Machine
[2023-05-30 14:01:35,574] {taskinstance.py:1252} INFO - Exporting the following env vars:
AIRFLOW_CTX_DAG_OWNER=airflow
AIRFLOW_CTX_DAG_ID=agile_data_science_batch_prediction_model_training
AIRFLOW_CTX_TASK_ID=pyspark_train_classifier_model
AIRFLOW_CTX_EXECUTION_DATE=2023-05-30T11:56:10.604104+00:00
AIRFLOW_CTX_DAG_RUN_ID=manual__2023-05-30T11:56:10.604104+00:00
[2023-05-30 14:01:35,576] {subprocess.py:52} INFO - Tmp dir root location: 
 /tmp
[2023-05-30 14:01:35,577] {subprocess.py:63} INFO - Running command: ['bash', '-c', '\nspark-submit --master local[8]   /home/lucia/practica_creativa///resources/train_spark_mllib_model.py   /home/lucia/practica_creativa//']
[2023-05-30 14:01:35,590] {subprocess.py:74} INFO - Output:
[2023-05-30 14:01:42,143] {subprocess.py:78} INFO - 23/05/30 14:01:42 WARN Utils: Your hostname, lucia-Virtual-Machine resolves to a loopback address: 127.0.1.1; using 192.168.1.104 instead (on interface eth0)
[2023-05-30 14:01:42,151] {subprocess.py:78} INFO - 23/05/30 14:01:42 WARN Utils: Set SPARK_LOCAL_IP if you need to bind to another address
[2023-05-30 14:01:43,703] {subprocess.py:78} INFO - Traceback (most recent call last):
[2023-05-30 14:01:43,703] {subprocess.py:78} INFO -   File "/home/lucia/practica_creativa/resources/train_spark_mllib_model.py", line 19, in main
[2023-05-30 14:01:43,705] {subprocess.py:78} INFO -     sc and spark
[2023-05-30 14:01:43,705] {subprocess.py:78} INFO - UnboundLocalError: local variable 'sc' referenced before assignment
[2023-05-30 14:01:43,705] {subprocess.py:78} INFO - 
[2023-05-30 14:01:43,706] {subprocess.py:78} INFO - During handling of the above exception, another exception occurred:
[2023-05-30 14:01:43,706] {subprocess.py:78} INFO - 
[2023-05-30 14:01:43,706] {subprocess.py:78} INFO - Traceback (most recent call last):
[2023-05-30 14:01:43,706] {subprocess.py:78} INFO -   File "/home/lucia/practica_creativa/resources/train_spark_mllib_model.py", line 190, in <module>
[2023-05-30 14:01:43,707] {subprocess.py:78} INFO -     main(sys.argv[1])
[2023-05-30 14:01:43,707] {subprocess.py:78} INFO -   File "/home/lucia/practica_creativa/resources/train_spark_mllib_model.py", line 21, in main
[2023-05-30 14:01:43,708] {subprocess.py:78} INFO -     import findspark
[2023-05-30 14:01:43,708] {subprocess.py:78} INFO - ModuleNotFoundError: No module named 'findspark'
[2023-05-30 14:01:43,737] {subprocess.py:78} INFO - 23/05/30 14:01:43 INFO ShutdownHookManager: Shutdown hook called
[2023-05-30 14:01:43,740] {subprocess.py:78} INFO - 23/05/30 14:01:43 INFO ShutdownHookManager: Deleting directory /tmp/spark-416b92bc-b416-4812-b8db-d10f1c637c51
[2023-05-30 14:01:43,822] {subprocess.py:82} INFO - Command exited with return code 1
[2023-05-30 14:01:43,841] {taskinstance.py:1463} ERROR - Task failed with exception
Traceback (most recent call last):
  File "/home/lucia/practica_creativa/resources/airflow/env/lib/python3.10/site-packages/airflow/models/taskinstance.py", line 1165, in _run_raw_task
    self._prepare_and_execute_task_with_callbacks(context, task)
  File "/home/lucia/practica_creativa/resources/airflow/env/lib/python3.10/site-packages/airflow/models/taskinstance.py", line 1283, in _prepare_and_execute_task_with_callbacks
    result = self._execute_task(context, task_copy)
  File "/home/lucia/practica_creativa/resources/airflow/env/lib/python3.10/site-packages/airflow/models/taskinstance.py", line 1313, in _execute_task
    result = task_copy.execute(context=context)
  File "/home/lucia/practica_creativa/resources/airflow/env/lib/python3.10/site-packages/airflow/operators/bash.py", line 176, in execute
    raise AirflowException('Bash command failed. The command returned a non-zero exit code.')
airflow.exceptions.AirflowException: Bash command failed. The command returned a non-zero exit code.
[2023-05-30 14:01:43,848] {taskinstance.py:1506} INFO - Marking task as UP_FOR_RETRY. dag_id=agile_data_science_batch_prediction_model_training, task_id=pyspark_train_classifier_model, execution_date=20230530T115610, start_date=20230530T120135, end_date=20230530T120143
[2023-05-30 14:01:43,909] {local_task_job.py:151} INFO - Task exited with return code 1
[2023-05-30 14:01:43,932] {local_task_job.py:261} INFO - 0 downstream tasks scheduled from follow-on schedule check
