[2023-05-30 14:36:36,318] {taskinstance.py:903} INFO - Dependencies all met for <TaskInstance: agile_data_science_batch_prediction_model_training.pyspark_train_classifier_model 2023-05-30T12:27:38.195702+00:00 [queued]>
[2023-05-30 14:36:36,333] {taskinstance.py:903} INFO - Dependencies all met for <TaskInstance: agile_data_science_batch_prediction_model_training.pyspark_train_classifier_model 2023-05-30T12:27:38.195702+00:00 [queued]>
[2023-05-30 14:36:36,333] {taskinstance.py:1095} INFO - 
--------------------------------------------------------------------------------
[2023-05-30 14:36:36,334] {taskinstance.py:1096} INFO - Starting attempt 1 of 4
[2023-05-30 14:36:36,334] {taskinstance.py:1097} INFO - 
--------------------------------------------------------------------------------
[2023-05-30 14:36:36,376] {taskinstance.py:1115} INFO - Executing <Task(BashOperator): pyspark_train_classifier_model> on 2023-05-30T12:27:38.195702+00:00
[2023-05-30 14:36:36,381] {standard_task_runner.py:52} INFO - Started process 136185 to run task
[2023-05-30 14:36:36,401] {standard_task_runner.py:76} INFO - Running: ['airflow', 'tasks', 'run', 'agile_data_science_batch_prediction_model_training', 'pyspark_train_classifier_model', '2023-05-30T12:27:38.195702+00:00', '--job-id', '9', '--pool', 'default_pool', '--raw', '--subdir', '/home/lucia/practica_creativa/resources/airflow/dags/setup.py', '--cfg-path', '/tmp/tmpmygdy2x2', '--error-file', '/tmp/tmp8h6hs1xc']
[2023-05-30 14:36:36,403] {standard_task_runner.py:77} INFO - Job 9: Subtask pyspark_train_classifier_model
[2023-05-30 14:36:36,572] {logging_mixin.py:109} INFO - Running <TaskInstance: agile_data_science_batch_prediction_model_training.pyspark_train_classifier_model 2023-05-30T12:27:38.195702+00:00 [running]> on host lucia-Virtual-Machine
[2023-05-30 14:36:36,642] {taskinstance.py:1252} INFO - Exporting the following env vars:
AIRFLOW_CTX_DAG_OWNER=airflow
AIRFLOW_CTX_DAG_ID=agile_data_science_batch_prediction_model_training
AIRFLOW_CTX_TASK_ID=pyspark_train_classifier_model
AIRFLOW_CTX_EXECUTION_DATE=2023-05-30T12:27:38.195702+00:00
AIRFLOW_CTX_DAG_RUN_ID=manual__2023-05-30T12:27:38.195702+00:00
[2023-05-30 14:36:36,645] {subprocess.py:52} INFO - Tmp dir root location: 
 /tmp
[2023-05-30 14:36:36,647] {subprocess.py:63} INFO - Running command: ['bash', '-c', '\nspark-submit --master local[8]   /home/lucia/practica_creativa///resources/train_spark_mllib_model.py   /home/lucia/practica_creativa//']
[2023-05-30 14:36:36,674] {subprocess.py:74} INFO - Output:
[2023-05-30 14:36:43,568] {subprocess.py:78} INFO - 23/05/30 14:36:43 WARN Utils: Your hostname, lucia-Virtual-Machine resolves to a loopback address: 127.0.1.1; using 192.168.1.104 instead (on interface eth0)
[2023-05-30 14:36:43,576] {subprocess.py:78} INFO - 23/05/30 14:36:43 WARN Utils: Set SPARK_LOCAL_IP if you need to bind to another address
[2023-05-30 14:36:45,103] {subprocess.py:78} INFO - Traceback (most recent call last):
[2023-05-30 14:36:45,106] {subprocess.py:78} INFO -   File "/home/lucia/practica_creativa/resources/train_spark_mllib_model.py", line 19, in main
[2023-05-30 14:36:45,107] {subprocess.py:78} INFO -     sc and spark
[2023-05-30 14:36:45,107] {subprocess.py:78} INFO - UnboundLocalError: local variable 'sc' referenced before assignment
[2023-05-30 14:36:45,108] {subprocess.py:78} INFO - 
[2023-05-30 14:36:45,108] {subprocess.py:78} INFO - During handling of the above exception, another exception occurred:
[2023-05-30 14:36:45,108] {subprocess.py:78} INFO - 
[2023-05-30 14:36:45,108] {subprocess.py:78} INFO - Traceback (most recent call last):
[2023-05-30 14:36:45,108] {subprocess.py:78} INFO -   File "/home/lucia/practica_creativa/resources/train_spark_mllib_model.py", line 190, in <module>
[2023-05-30 14:36:45,109] {subprocess.py:78} INFO -     main(sys.argv[1])
[2023-05-30 14:36:45,109] {subprocess.py:78} INFO -   File "/home/lucia/practica_creativa/resources/train_spark_mllib_model.py", line 21, in main
[2023-05-30 14:36:45,109] {subprocess.py:78} INFO -     import findspark
[2023-05-30 14:36:45,109] {subprocess.py:78} INFO - ModuleNotFoundError: No module named 'findspark'
[2023-05-30 14:36:45,141] {subprocess.py:78} INFO - 23/05/30 14:36:45 INFO ShutdownHookManager: Shutdown hook called
[2023-05-30 14:36:45,143] {subprocess.py:78} INFO - 23/05/30 14:36:45 INFO ShutdownHookManager: Deleting directory /tmp/spark-7066f25b-ce6c-4e42-976d-0b29643f957a
[2023-05-30 14:36:45,215] {subprocess.py:82} INFO - Command exited with return code 1
[2023-05-30 14:36:45,237] {taskinstance.py:1463} ERROR - Task failed with exception
Traceback (most recent call last):
  File "/home/lucia/practica_creativa/resources/airflow/env/lib/python3.10/site-packages/airflow/models/taskinstance.py", line 1165, in _run_raw_task
    self._prepare_and_execute_task_with_callbacks(context, task)
  File "/home/lucia/practica_creativa/resources/airflow/env/lib/python3.10/site-packages/airflow/models/taskinstance.py", line 1283, in _prepare_and_execute_task_with_callbacks
    result = self._execute_task(context, task_copy)
  File "/home/lucia/practica_creativa/resources/airflow/env/lib/python3.10/site-packages/airflow/models/taskinstance.py", line 1313, in _execute_task
    result = task_copy.execute(context=context)
  File "/home/lucia/practica_creativa/resources/airflow/env/lib/python3.10/site-packages/airflow/operators/bash.py", line 176, in execute
    raise AirflowException('Bash command failed. The command returned a non-zero exit code.')
airflow.exceptions.AirflowException: Bash command failed. The command returned a non-zero exit code.
[2023-05-30 14:36:45,244] {taskinstance.py:1506} INFO - Marking task as UP_FOR_RETRY. dag_id=agile_data_science_batch_prediction_model_training, task_id=pyspark_train_classifier_model, execution_date=20230530T122738, start_date=20230530T123636, end_date=20230530T123645
[2023-05-30 14:36:45,297] {local_task_job.py:151} INFO - Task exited with return code 1
[2023-05-30 14:36:45,320] {local_task_job.py:261} INFO - 0 downstream tasks scheduled from follow-on schedule check
